{"uuid": "09724ae7-fecc-4218-9ae9-e4b2f8ba2ca4", "children": ["db6581d0-8cd3-41f6-8a7a-1f0810af3777"], "befores": [{"name": "setup_teardown", "status": "broken", "statusDetails": {"message": "urllib3.exceptions.MaxRetryError: HTTPConnectionPool(host='127.0.0.1', port=4723): Max retries exceeded with url: /wd/hub/session (Caused by NewConnectionError('<urllib3.connection.HTTPConnection object at 0x0D31A630>: Failed to establish a new connection: [WinError 10061] 由于目标计算机积极拒绝，无法连接。'))\n", "trace": "  File \"C:\\Users\\syz\\AppData\\Local\\Programs\\Python\\Python37-32\\lib\\site-packages\\pluggy\\_callers.py\", line 39, in _multicall\n    res = hook_impl.function(*args)\n  File \"C:\\Users\\syz\\AppData\\Local\\Programs\\Python\\Python37-32\\lib\\site-packages\\_pytest\\fixtures.py\", line 1126, in pytest_fixture_setup\n    result = call_fixture_func(fixturefunc, request, kwargs)\n  File \"C:\\Users\\syz\\AppData\\Local\\Programs\\Python\\Python37-32\\lib\\site-packages\\_pytest\\fixtures.py\", line 925, in call_fixture_func\n    fixture_result = next(generator)\n  File \"D:\\python_Code\\pythonProject\\pythonclasses\\autoclass\\day06\\appautotest\\conftest.py\", line 27, in setup_teardown\n    driver = webdriver.Remote(\"http://127.0.0.1:4723/wd/hub\", Caps.caps_auto_device_notstart)\n  File \"C:\\Users\\syz\\AppData\\Local\\Programs\\Python\\Python37-32\\lib\\site-packages\\appium\\webdriver\\webdriver.py\", line 275, in __init__\n    AppiumConnection(command_executor, keep_alive=keep_alive), desired_capabilities, browser_profile, proxy\n  File \"C:\\Users\\syz\\AppData\\Local\\Programs\\Python\\Python37-32\\lib\\site-packages\\selenium\\webdriver\\remote\\webdriver.py\", line 269, in __init__\n    self.start_session(capabilities, browser_profile)\n  File \"C:\\Users\\syz\\AppData\\Local\\Programs\\Python\\Python37-32\\lib\\site-packages\\appium\\webdriver\\webdriver.py\", line 369, in start_session\n    response = self.execute(RemoteCommand.NEW_SESSION, parameters)\n  File \"C:\\Users\\syz\\AppData\\Local\\Programs\\Python\\Python37-32\\lib\\site-packages\\selenium\\webdriver\\remote\\webdriver.py\", line 423, in execute\n    response = self.command_executor.execute(driver_command, params)\n  File \"C:\\Users\\syz\\AppData\\Local\\Programs\\Python\\Python37-32\\lib\\site-packages\\selenium\\webdriver\\remote\\remote_connection.py\", line 316, in execute\n    return self._request(command_info[0], url, body=data)\n  File \"C:\\Users\\syz\\AppData\\Local\\Programs\\Python\\Python37-32\\lib\\site-packages\\selenium\\webdriver\\remote\\remote_connection.py\", line 338, in _request\n    resp = self._conn.request(method, url, body=body, headers=headers)\n  File \"C:\\Users\\syz\\AppData\\Local\\Programs\\Python\\Python37-32\\lib\\site-packages\\urllib3\\request.py\", line 79, in request\n    method, url, fields=fields, headers=headers, **urlopen_kw\n  File \"C:\\Users\\syz\\AppData\\Local\\Programs\\Python\\Python37-32\\lib\\site-packages\\urllib3\\request.py\", line 170, in request_encode_body\n    return self.urlopen(method, url, **extra_kw)\n  File \"C:\\Users\\syz\\AppData\\Local\\Programs\\Python\\Python37-32\\lib\\site-packages\\urllib3\\poolmanager.py\", line 376, in urlopen\n    response = conn.urlopen(method, u.request_uri, **kw)\n  File \"C:\\Users\\syz\\AppData\\Local\\Programs\\Python\\Python37-32\\lib\\site-packages\\urllib3\\connectionpool.py\", line 828, in urlopen\n    **response_kw\n  File \"C:\\Users\\syz\\AppData\\Local\\Programs\\Python\\Python37-32\\lib\\site-packages\\urllib3\\connectionpool.py\", line 828, in urlopen\n    **response_kw\n  File \"C:\\Users\\syz\\AppData\\Local\\Programs\\Python\\Python37-32\\lib\\site-packages\\urllib3\\connectionpool.py\", line 828, in urlopen\n    **response_kw\n  File \"C:\\Users\\syz\\AppData\\Local\\Programs\\Python\\Python37-32\\lib\\site-packages\\urllib3\\connectionpool.py\", line 788, in urlopen\n    method, url, error=e, _pool=self, _stacktrace=sys.exc_info()[2]\n  File \"C:\\Users\\syz\\AppData\\Local\\Programs\\Python\\Python37-32\\lib\\site-packages\\urllib3\\util\\retry.py\", line 592, in increment\n    raise MaxRetryError(_pool, url, error or ResponseError(cause))\n"}, "start": 1685281485053, "stop": 1685281493074}], "start": 1685281485053, "stop": 1685281493282}