{"uuid": "f3e52ca0-3464-48cb-90eb-801676e1c3ac", "children": ["61fa89ce-89ec-418d-b449-0b0a41e6d752", "c56240bd-4817-4e57-9c92-4c7cff402e84"], "befores": [{"name": "setup_teardown", "status": "broken", "statusDetails": {"message": "selenium.common.exceptions.WebDriverException: Message: An unknown server-side error occurred while processing the command. Original error: Cannot verify the signature of 'C:\\Users\\syz\\AppData\\Local\\Temp\\202354-16692-1wg0m7f.st8u\\appium-uiautomator2-server-v4.17.4.apk'. Original error: Error occurred during initialization of VM\nCould not reserve enough space for object heap\n\nStacktrace:\nUnknownError: An unknown server-side error occurred while processing the command. Original error: Cannot verify the signature of 'C:\\Users\\syz\\AppData\\Local\\Temp\\202354-16692-1wg0m7f.st8u\\appium-uiautomator2-server-v4.17.4.apk'. Original error: Error occurred during initialization of VM\nCould not reserve enough space for object heap\n\n    at getResponseForW3CError (C:\\Program Files\\Appium\\resources\\app\\node_modules\\appium\\node_modules\\appium-base-driver\\lib\\protocol\\errors.js:804:9)\n    at asyncHandler (C:\\Program Files\\Appium\\resources\\app\\node_modules\\appium\\node_modules\\appium-base-driver\\lib\\protocol\\protocol.js:380:37)\n", "trace": "  File \"C:\\Users\\syz\\AppData\\Local\\Programs\\Python\\Python37-32\\lib\\site-packages\\pluggy\\_callers.py\", line 39, in _multicall\n    res = hook_impl.function(*args)\n  File \"C:\\Users\\syz\\AppData\\Local\\Programs\\Python\\Python37-32\\lib\\site-packages\\_pytest\\fixtures.py\", line 1126, in pytest_fixture_setup\n    result = call_fixture_func(fixturefunc, request, kwargs)\n  File \"C:\\Users\\syz\\AppData\\Local\\Programs\\Python\\Python37-32\\lib\\site-packages\\_pytest\\fixtures.py\", line 925, in call_fixture_func\n    fixture_result = next(generator)\n  File \"D:\\python_Code\\pythonProject\\pythonclasses\\autoclass\\day07\\appautotest\\conftest.py\", line 28, in setup_teardown\n    driver = webdriver.Remote(\"http://127.0.0.1:4723/wd/hub\", Caps.caps_for_xiaomishop)\n  File \"C:\\Users\\syz\\AppData\\Local\\Programs\\Python\\Python37-32\\lib\\site-packages\\appium\\webdriver\\webdriver.py\", line 275, in __init__\n    AppiumConnection(command_executor, keep_alive=keep_alive), desired_capabilities, browser_profile, proxy\n  File \"C:\\Users\\syz\\AppData\\Local\\Programs\\Python\\Python37-32\\lib\\site-packages\\selenium\\webdriver\\remote\\webdriver.py\", line 269, in __init__\n    self.start_session(capabilities, browser_profile)\n  File \"C:\\Users\\syz\\AppData\\Local\\Programs\\Python\\Python37-32\\lib\\site-packages\\appium\\webdriver\\webdriver.py\", line 369, in start_session\n    response = self.execute(RemoteCommand.NEW_SESSION, parameters)\n  File \"C:\\Users\\syz\\AppData\\Local\\Programs\\Python\\Python37-32\\lib\\site-packages\\selenium\\webdriver\\remote\\webdriver.py\", line 425, in execute\n    self.error_handler.check_response(response)\n  File \"C:\\Users\\syz\\AppData\\Local\\Programs\\Python\\Python37-32\\lib\\site-packages\\selenium\\webdriver\\remote\\errorhandler.py\", line 247, in check_response\n    raise exception_class(message, screen, stacktrace)\n"}, "start": 1685856431401, "stop": 1685856434643}], "start": 1685856431401, "stop": 1685856434940}