{"uuid": "090804e2-7a1d-4744-8ae5-f04fa95f4d26", "children": ["8ae780c1-fadb-40e1-912f-8b31dd3b5703", "e8c0f4bd-dcb3-4923-97ff-6dfeee57b703", "b7af1e29-f0af-46a3-a797-0e08e4bbd107"], "befores": [{"name": "setup_teardown", "status": "broken", "statusDetails": {"message": "selenium.common.exceptions.WebDriverException: Message: An unknown server-side error occurred while processing the command. Original error: Cannot start the 'com.xiaomi.shop' application. Visit https://github.com/appium/appium/blob/master/docs/en/writing-running-appium/android/activity-startup.md for troubleshooting. Original error: Activity for intent 'android.intent.action.MAIN' used to start the app doesn't exist or cannot be launched! Make sure it exists and is a launchable activity\nStacktrace:\nUnknownError: An unknown server-side error occurred while processing the command. Original error: Cannot start the 'com.xiaomi.shop' application. Visit https://github.com/appium/appium/blob/master/docs/en/writing-running-appium/android/activity-startup.md for troubleshooting. Original error: Activity for intent 'android.intent.action.MAIN' used to start the app doesn't exist or cannot be launched! Make sure it exists and is a launchable activity\n    at getResponseForW3CError (C:\\Program Files\\Appium\\resources\\app\\node_modules\\appium\\node_modules\\appium-base-driver\\lib\\protocol\\errors.js:804:9)\n    at asyncHandler (C:\\Program Files\\Appium\\resources\\app\\node_modules\\appium\\node_modules\\appium-base-driver\\lib\\protocol\\protocol.js:380:37)\n", "trace": "  File \"C:\\Users\\syz\\AppData\\Local\\Programs\\Python\\Python37-32\\lib\\site-packages\\pluggy\\_callers.py\", line 39, in _multicall\n    res = hook_impl.function(*args)\n  File \"C:\\Users\\syz\\AppData\\Local\\Programs\\Python\\Python37-32\\lib\\site-packages\\_pytest\\fixtures.py\", line 1126, in pytest_fixture_setup\n    result = call_fixture_func(fixturefunc, request, kwargs)\n  File \"C:\\Users\\syz\\AppData\\Local\\Programs\\Python\\Python37-32\\lib\\site-packages\\_pytest\\fixtures.py\", line 925, in call_fixture_func\n    fixture_result = next(generator)\n  File \"D:\\python_Code\\pythonProject\\pythonclasses\\autoclass\\day06\\appautotest\\conftest.py\", line 27, in setup_teardown\n    driver = webdriver.Remote(\"http://127.0.0.1:4723/wd/hub\", Caps.caps_auto_device_notstart)\n  File \"C:\\Users\\syz\\AppData\\Local\\Programs\\Python\\Python37-32\\lib\\site-packages\\appium\\webdriver\\webdriver.py\", line 275, in __init__\n    AppiumConnection(command_executor, keep_alive=keep_alive), desired_capabilities, browser_profile, proxy\n  File \"C:\\Users\\syz\\AppData\\Local\\Programs\\Python\\Python37-32\\lib\\site-packages\\selenium\\webdriver\\remote\\webdriver.py\", line 269, in __init__\n    self.start_session(capabilities, browser_profile)\n  File \"C:\\Users\\syz\\AppData\\Local\\Programs\\Python\\Python37-32\\lib\\site-packages\\appium\\webdriver\\webdriver.py\", line 369, in start_session\n    response = self.execute(RemoteCommand.NEW_SESSION, parameters)\n  File \"C:\\Users\\syz\\AppData\\Local\\Programs\\Python\\Python37-32\\lib\\site-packages\\selenium\\webdriver\\remote\\webdriver.py\", line 425, in execute\n    self.error_handler.check_response(response)\n  File \"C:\\Users\\syz\\AppData\\Local\\Programs\\Python\\Python37-32\\lib\\site-packages\\selenium\\webdriver\\remote\\errorhandler.py\", line 247, in check_response\n    raise exception_class(message, screen, stacktrace)\n"}, "start": 1685785614827, "stop": 1685785627654}], "start": 1685785614827, "stop": 1685785628053}