{"uuid": "82076cee-14a2-4d61-a444-585da73db071", "children": ["034ee639-f083-4a68-8038-56f6218e3f6e", "819879bb-c178-4216-9dd4-cabf1d781247"], "befores": [{"name": "setup_teardown", "status": "broken", "statusDetails": {"message": "selenium.common.exceptions.WebDriverException: Message: An unknown server-side error occurred while processing the command. Original error: Cannot verify the signature of 'C:\\Users\\syz\\AppData\\Local\\Temp\\202354-23592-php3b9.38k0s\\appium-uiautomator2-server-v4.17.4.apk'. Original error: #\n# There is insufficient memory for the Java Runtime Environment to continue.\n# Native memory allocation (malloc) failed to allocate 1048576 bytes for AllocateHeap\n# An error report file with more information is saved as:\n# D:\\download\\app soft\\android-sdk\\build-tools\\30.0.3\\lib\\hs_err_pid20892.log\n\nStacktrace:\nUnknownError: An unknown server-side error occurred while processing the command. Original error: Cannot verify the signature of 'C:\\Users\\syz\\AppData\\Local\\Temp\\202354-23592-php3b9.38k0s\\appium-uiautomator2-server-v4.17.4.apk'. Original error: #\n# There is insufficient memory for the Java Runtime Environment to continue.\n# Native memory allocation (malloc) failed to allocate 1048576 bytes for AllocateHeap\n# An error report file with more information is saved as:\n# D:\\download\\app soft\\android-sdk\\build-tools\\30.0.3\\lib\\hs_err_pid20892.log\n\n    at getResponseForW3CError (C:\\Program Files\\Appium\\resources\\app\\node_modules\\appium\\node_modules\\appium-base-driver\\lib\\protocol\\errors.js:804:9)\n    at asyncHandler (C:\\Program Files\\Appium\\resources\\app\\node_modules\\appium\\node_modules\\appium-base-driver\\lib\\protocol\\protocol.js:380:37)\n", "trace": "  File \"C:\\Users\\syz\\AppData\\Local\\Programs\\Python\\Python37-32\\lib\\site-packages\\pluggy\\_callers.py\", line 39, in _multicall\n    res = hook_impl.function(*args)\n  File \"C:\\Users\\syz\\AppData\\Local\\Programs\\Python\\Python37-32\\lib\\site-packages\\_pytest\\fixtures.py\", line 1126, in pytest_fixture_setup\n    result = call_fixture_func(fixturefunc, request, kwargs)\n  File \"C:\\Users\\syz\\AppData\\Local\\Programs\\Python\\Python37-32\\lib\\site-packages\\_pytest\\fixtures.py\", line 925, in call_fixture_func\n    fixture_result = next(generator)\n  File \"D:\\python_Code\\pythonProject\\pythonclasses\\autoclass\\day07\\appautotest\\conftest.py\", line 28, in setup_teardown\n    driver = webdriver.Remote(\"http://127.0.0.1:4723/wd/hub\", Caps.caps_for_xiaomishop)\n  File \"C:\\Users\\syz\\AppData\\Local\\Programs\\Python\\Python37-32\\lib\\site-packages\\appium\\webdriver\\webdriver.py\", line 275, in __init__\n    AppiumConnection(command_executor, keep_alive=keep_alive), desired_capabilities, browser_profile, proxy\n  File \"C:\\Users\\syz\\AppData\\Local\\Programs\\Python\\Python37-32\\lib\\site-packages\\selenium\\webdriver\\remote\\webdriver.py\", line 269, in __init__\n    self.start_session(capabilities, browser_profile)\n  File \"C:\\Users\\syz\\AppData\\Local\\Programs\\Python\\Python37-32\\lib\\site-packages\\appium\\webdriver\\webdriver.py\", line 369, in start_session\n    response = self.execute(RemoteCommand.NEW_SESSION, parameters)\n  File \"C:\\Users\\syz\\AppData\\Local\\Programs\\Python\\Python37-32\\lib\\site-packages\\selenium\\webdriver\\remote\\webdriver.py\", line 425, in execute\n    self.error_handler.check_response(response)\n  File \"C:\\Users\\syz\\AppData\\Local\\Programs\\Python\\Python37-32\\lib\\site-packages\\selenium\\webdriver\\remote\\errorhandler.py\", line 247, in check_response\n    raise exception_class(message, screen, stacktrace)\n"}, "start": 1685855918811, "stop": 1685855922044}], "start": 1685855918811, "stop": 1685855922251}